Workbook

Sheet Roster
A1: Tournament | B1: Seed | C1: Name | D1: Nickname | E1: Hometown | F1: Style | G1: Technique | H1: Signature punch | I1: Skill (0-1) | J1: Danger (1-10) | K1: Toughness | L1: Power | M1: Takes damage | N1: Hair | O1: Hair colour | P1: Facial hair | Q1: Face | R1: Eyebrows | S1: Skin | T1: Eyes | U1: Build | V1: Shorts | W1: Shorts colour | X1: Trim | Y1: Top | Z1: Headgear | AA1: Gloves | AB1: Boots | AC1: Sole
A2: Amateur | B2: 1 | C2: Kwame Mendes | D2: The Surveyor | E2: Accra | F2: Out-boxer | G2: Stays long behind a stiff jab and keeps moving. Hard to reach, rarely trades. | H2: Body jab | I2: 0.45 | J2: =MAX(1,MIN(10,ROUND(I2*8+IF(A2="Amateur",0.5,1),0))) -> 4 | K2: 1 | L2: 1 | M2: =1/K2 -> 1 | N2: Mohawk | O2: Ginger | P2: Clean shaven | Q2: Square jaw | R2: Thin | S2: Brown | T2: Grey | U2: Very lean, toned | V2: Classic trunks | W2: Green | X2: White | Y2: Vest · Green | Z2: No | AA2: White | AB2: Classic boots · Blue | AC2: Black
A3: Amateur | B3: 2 | C3: Teodor Fontaine | D3: Steamroller | E3: Cebu | F3: Swarmer | G3: Walks you down and never stops throwing. Lives on the inside with hooks. | H3: Body hook | I3: 0.418 | J3: =MAX(1,MIN(10,ROUND(I3*8+IF(A3="Amateur",0.5,1),0))) -> 4 | K3: 1 | L3: 0.993 | M3: =1/K3 -> 1 | N3: Twists | O3: Grey | P3: Clean shaven | Q3: Brawler | R3: Regular | S3: Light | T3: Hazel | U3: Middleweight, built | V3: Classic trunks | W3: Gold | X3: Orange | Y3: Vest · Gold | Z3: Yes | AA3: Orange | AB3: Classic boots · White | AC3: Gum
A4: Amateur | B4: 3 | C4: Bruno Brandt | D4: Hammerhead | E4: Glasgow | F4: Slugger | G4: Slow feet, heavy hands. Waits for one big hook or uppercut to end it. | H4: Right uppercut | I4: 0.386 | J4: =MAX(1,MIN(10,ROUND(I4*8+IF(A4="Amateur",0.5,1),0))) -> 4 | K4: 1 | L4: 1.104 | M4: =1/K4 -> 1 | N4: Afro | O4: Ginger | P4: Clean shaven | Q4: Wide nose | R4: Regular | S4: Brown | T4: Blue | U4: Heavy, toned | V4: Classic trunks | W4: Silver | X4: Purple | Y4: Vest · Silver | Z4: No | AA4: Purple | AB4: Classic boots · Silver | AC4: Gum
A5: Amateur | B5: 4 | C5: Tariq Zielinski | D5: Pitbull | E5: Sarajevo | F5: Swarmer | G5: Walks you down and never stops throwing. Lives on the inside with hooks. | H5: Left hook | I5: 0.354 | J5: =MAX(1,MIN(10,ROUND(I5*8+IF(A5="Amateur",0.5,1),0))) -> 3 | K5: 1 | L5: 0.979 | M5: =1/K5 -> 1 | N5: Bald | P5: Clean shaven | Q5: Sharp | R5: Regular | S5: Fair | T5: Green | U5: Middleweight, toned | V5: Long trunks | W5: Black | X5: Red | Y5: Bare chest | Z5: No | AA5: White | AB5: Classic boots · Blue | AC5: Black
A6: Amateur | B6: 5 | C6: Ravi Quinlan | D6: Turtle | E6: Halifax | F6: Shell guard | G6: Hides behind a high guard, takes your best shots on the arms, then breaks yours. | H6: Body hook | I6: 0.321 | J6: =MAX(1,MIN(10,ROUND(I6*8+IF(A6="Amateur",0.5,1),0))) -> 3 | K6: 1.08 | L6: 0.971 | M6: =1/K6 -> 0.92592593 | N6: Crew cut | O6: Pink dye | P6: Clean shaven | Q6: Brawler | R6: Regular | S6: Fair | T6: Green | U6: Heavy, bodybuilder | V6: Long trunks | W6: Pink | X6: Black | Y6: Bare chest | Z6: Yes | AA6: White | AB6: Classic boots · Red | AC6: Black
A7: Amateur | B7: 6 | C7: Fintan Cruz | D7: Hollywood | E7: Mombasa | F7: Showman | G7: Flashy and loud. Throws in flurries, taunts when ahead, can be caught showing off. | H7: Long right hook | I7: 0.289 | J7: =MAX(1,MIN(10,ROUND(I7*8+IF(A7="Amateur",0.5,1),0))) -> 3 | K7: 1 | L7: 0.964 | M7: =1/K7 -> 1 | N7: Faux hawk | O7: Bleached | P7: Clean shaven | Q7: Brawler | R7: Regular | S7: Tan | T7: Grey | U7: Lean, built | V7: Classic trunks | W7: Green | X7: Silver | Y7: Vest · Green | Z7: No | AA7: Silver | AB7: Classic boots · Gold | AC7: White
A8: Amateur | B8: 7 | C8: Vikram Lombardi | D8: The Drummer | E8: Accra | F8: Volume puncher | G8: Fast, light punches in long bunches. Wins rounds on work rate. | H8: Double jab | I8: 0.257 | J8: =MAX(1,MIN(10,ROUND(I8*8+IF(A8="Amateur",0.5,1),0))) -> 3 | K8: 1 | L8: 0.861 | M8: =1/K8 -> 1 | N8: Bald | P8: Clean shaven | Q8: Strong chin | R8: Regular | S8: Brown | T8: Blue | U8: Middleweight, toned | V8: Long trunks | W8: Crimson | X8: Orange | Y8: Vest · Crimson | Z8: Yes | AA8: Orange | AB8: High boots · White | AC8: White
A9: Amateur | B9: 8 | C9: Santiago Petrov | D9: Mirage | E9: Tbilisi | F9: Slick defender | G9: Slips, ducks and rolls everything, then pecks at you from odd angles. | H9: Double jab | I9: 0.225 | J9: =MAX(1,MIN(10,ROUND(I9*8+IF(A9="Amateur",0.5,1),0))) -> 2 | K9: 1 | L9: 0.95 | M9: =1/K9 -> 1 | N9: High-top fade | O9: Dark brown | P9: Clean shaven | Q9: Original | R9: Regular | S9: Fair | T9: Blue | U9: Lean, toned | V9: Classic trunks | W9: Crimson | X9: Maroon | Y9: Bare chest | Z9: No | AA9: Maroon | AB9: High boots · White | AC9: Black
A10: Amateur | B10: 9 | C10: Duncan Cruz | D10: Long Arm | E10: Cardiff | F10: Out-boxer | G10: Stays long behind a stiff jab and keeps moving. Hard to reach, rarely trades. | H10: Stiff cross | I10: 0.193 | J10: =MAX(1,MIN(10,ROUND(I10*8+IF(A10="Amateur",0.5,1),0))) -> 2 | K10: 1 | L10: 0.943 | M10: =1/K10 -> 1 | N10: Bald | P10: Clean shaven | Q10: Strong chin | R10: Regular | S10: Brown | T10: Blue | U10: Very lean, lean | V10: Classic trunks | W10: Black | X10: Emerald | Y10: Vest · Black | Z10: No | AA10: Black | AB10: Classic boots · White | AC10: Black
A11: Amateur | B11: 10 | C11: Hiro Sato | D11: The Butcher | E11: Medellín | F11: Body snatcher | G11: Digs to the ribs and the liver round after round until your legs go. | H11: Liver shot | I11: 0.161 | J11: =MAX(1,MIN(10,ROUND(I11*8+IF(A11="Amateur",0.5,1),0))) -> 2 | K11: 1 | L11: 0.936 | M11: =1/K11 -> 1 | N11: Crew cut | O11: Grey | P11: Beard | Q11: Square jaw | R11: Regular | S11: Brown | T11: Brown | U11: Middleweight, built | V11: Classic trunks | W11: Navy | X11: Blue | Y11: Vest · Navy | Z11: Yes | AA11: White | AB11: Low boots · Silver | AC11: Black
A12: Amateur | B12: 11 | C12: Callum Vasquez | D12: Wrecking Ball | E12: Valencia | F12: Slugger | G12: Slow feet, heavy hands. Waits for one big hook or uppercut to end it. | H12: Guard breaker | I12: 0.129 | J12: =MAX(1,MIN(10,ROUND(I12*8+IF(A12="Amateur",0.5,1),0))) -> 2 | K12: 1 | L12: 1.04 | M12: =1/K12 -> 1 | N12: Afro | O12: Ginger | P12: Clean shaven | Q12: Strong chin | R12: Regular | S12: Dark brown | T12: Blue | U12: Heavy, built | V12: Classic trunks | W12: Gold | X12: Pink | Y12: Vest · Gold | Z12: No | AA12: Black | AB12: Low boots · Blue | AC12: White
A13: Amateur | B13: 12 | C13: Pavel Vasquez | D13: Gut Check | E13: Rotterdam | F13: Body snatcher | G13: Digs to the ribs and the liver round after round until your legs go. | H13: Liver shot | I13: 0.096 | J13: =MAX(1,MIN(10,ROUND(I13*8+IF(A13="Amateur",0.5,1),0))) -> 1 | K13: 1 | L13: 0.921 | M13: =1/K13 -> 1 | N13: Buns | O13: Auburn | P13: Clean shaven | Q13: Original | R13: Regular | S13: Deep | T13: Blue | U13: Heavy, built | V13: Classic trunks | W13: Black | X13: Navy | Y13: Vest · Black | Z13: Yes | AA13: Navy | AB13: Low boots · Black | AC13: Black
A14: Amateur | B14: 13 | C14: Declan Moretti | D14: Rebound | E14: Cebu | F14: Counter-puncher | G14: Lets you lead, slips or blocks, then fires back before you reset. | H14: Stiff cross | I14: 0.064 | J14: =MAX(1,MIN(10,ROUND(I14*8+IF(A14="Amateur",0.5,1),0))) -> 1 | K14: 1 | L14: 0.914 | M14: =1/K14 -> 1 | N14: Crew cut | O14: Grey | P14: Clean shaven | Q14: Original | R14: Regular | S14: Light | T14: Blue | U14: Middleweight, built | V14: Long trunks | W14: Emerald | X14: Red | Y14: Bare chest | Z14: Yes | AA14: Black | AB14: High boots · Black | AC14: Black
A15: Amateur | B15: 14 | C15: Sven Grieve | D15: Snapback | E15: Tijuana | F15: Counter-puncher | G15: Lets you lead, slips or blocks, then fires back before you reset. | H15: Right uppercut | I15: 0.032 | J15: =MAX(1,MIN(10,ROUND(I15*8+IF(A15="Amateur",0.5,1),0))) -> 1 | K15: 1 | L15: 0.907 | M15: =1/K15 -> 1 | N15: Buzzed | O15: Brown | P15: Clean shaven | Q15: Brawler | R15: Regular | S15: Fair | T15: Dark brown | U15: Middleweight, toned | V15: Long trunks | W15: Teal | X15: Gold | Y15: Vest · Teal | Z15: No | AA15: Gold | AB15: Classic boots · Red | AC15: Gum
A16: Amateur | B16: 15 | C16: Gideon Marsh | D16: Slipstream | E16: Medellín | F16: Slick defender | G16: Slips, ducks and rolls everything, then pecks at you from odd angles. | H16: Double jab | I16: 0 | J16: =MAX(1,MIN(10,ROUND(I16*8+IF(A16="Amateur",0.5,1),0))) -> 1 | K16: 1 | L16: 0.9 | M16: =1/K16 -> 1 | N16: Afro | O16: Pink dye | P16: Clean shaven | Q16: Round and soft | R16: Regular | S16: Tan | T16: Dark brown | U16: Lean, toned | V16: Classic trunks | W16: Black | X16: Pink | Y16: Vest · Black | Z16: Yes | AA16: Pink | AB16: High boots · Blue | AC16: Gum
A17: Pro | B17: 1 | C17: Rocco Laurent | D17: Sledgehammer | E17: Kraków | F17: Slugger | G17: Slow feet, heavy hands. Waits for one big hook or uppercut to end it. | H17: Right uppercut | I17: 0.75 | J17: =MAX(1,MIN(10,ROUND(I17*8+IF(A17="Amateur",0.5,1),0))) -> 7 | K17: 1.14 | L17: 1.21 | M17: =1/K17 -> 0.87719298 | N17: Pompadour | O17: Auburn | P17: Beard | Q17: Original | R17: Regular | S17: Deep | T17: Green | U17: Heavy, built | V17: Classic trunks | W17: Black | X17: Sky | Y17: Bare chest | Z17: No | AA17: Sky | AB17: High boots · White | AC17: Black
A18: Pro | B18: 2 | C18: Ronan Grieve | D18: Rib Breaker | E18: Valencia | F18: Body snatcher | G18: Digs to the ribs and the liver round after round until your legs go. | H18: Body jab | I18: 0.721 | J18: =MAX(1,MIN(10,ROUND(I18*8+IF(A18="Amateur",0.5,1),0))) -> 7 | K18: 1.133 | L18: 1.074 | M18: =1/K18 -> 0.88261253 | N18: High-top fade | O18: Auburn | P18: Clean shaven | Q18: Original | R18: Regular | S18: Light | T18: Hazel | U18: Middleweight, built | V18: Long trunks | W18: Purple | X18: Navy | Y18: Bare chest | Z18: No | AA18: Purple | AB18: High boots · Gold | AC18: White
A19: Pro | B19: 3 | C19: Obi Farrell | D19: The Vault | E19: Lagos | F19: Shell guard | G19: Hides behind a high guard, takes your best shots on the arms, then breaks yours. | H19: Guard breaker | I19: 0.693 | J19: =MAX(1,MIN(10,ROUND(I19*8+IF(A19="Amateur",0.5,1),0))) -> 7 | K19: 1.216 | L19: 1.069 | M19: =1/K19 -> 0.82236842 | N19: Flat top | O19: Black | P19: Clean shaven | Q19: Square jaw | R19: Regular | S19: Brown | T19: Blue | U19: Middleweight, bodybuilder | V19: Classic trunks | W19: Pink | X19: Sky | Y19: Bare chest | Z19: No | AA19: White | AB19: Low boots · Gold | AC19: White
A20: Pro | B20: 4 | C20: Emeka Zielinski | D20: Metronome | E20: Perth | F20: Out-boxer | G20: Stays long behind a stiff jab and keeps moving. Hard to reach, rarely trades. | H20: Double jab | I20: 0.664 | J20: =MAX(1,MIN(10,ROUND(I20*8+IF(A20="Amateur",0.5,1),0))) -> 6 | K20: 1.119 | L20: 1.063 | M20: =1/K20 -> 0.89365505 | N20: Faux hawk | O20: Brown | P20: Clean shaven | Q20: Original | R20: Regular | S20: Dark brown | T20: Grey | U20: Very lean, toned | V20: Classic trunks | W20: Orange | X20: Red | Y20: Bare chest | Z20: No | AA20: Red | AB20: High boots · Gold | AC20: Gum
A21: Pro | B21: 5 | C21: Silas Mendes | D21: Payback | E21: Manila | F21: Counter-puncher | G21: Lets you lead, slips or blocks, then fires back before you reset. | H21: Stiff cross | I21: 0.636 | J21: =MAX(1,MIN(10,ROUND(I21*8+IF(A21="Amateur",0.5,1),0))) -> 6 | K21: 1.111 | L21: 1.057 | M21: =1/K21 -> 0.90009001 | N21: Twists | O21: Auburn | P21: Clean shaven | Q21: Brawler | R21: Regular | S21: Brown | T21: Dark brown | U21: Lean, built | V21: Long trunks | W21: Black | X21: White | Y21: Bare chest | Z21: No | AA21: Black | AB21: Low boots · Blue | AC21: Gum
A22: Pro | B22: 6 | C22: Paolo Sandoval | D22: Machine Gun | E22: Hamburg | F22: Volume puncher | G22: Fast, light punches in long bunches. Wins rounds on work rate. | H22: Left hook | I22: 0.607 | J22: =MAX(1,MIN(10,ROUND(I22*8+IF(A22="Amateur",0.5,1),0))) -> 6 | K22: 1.104 | L22: 0.946 | M22: =1/K22 -> 0.9057971 | N22: Simple parted | O22: Dark brown | P22: Beard | Q22: Brawler | R22: Thin | S22: Tan | T22: Grey | U22: Middleweight, toned | V22: Long trunks | W22: Pink | X22: Red | Y22: Bare chest | Z22: No | AA22: Black | AB22: Classic boots · Black | AC22: White
... A27: Pro | B27: 11 | C27: Ilya Dossou | D27: The Ghost | E27: Cardiff | F27: Slick defender | G27: Slips, ducks and rolls everything, then pecks at you from odd angles. | H27: Left hook | I27: 0.464 | J27: =MAX(1,MIN(10,ROUND(I27*8+IF(A27="Amateur",0.5,1),0))) -> 5 | K27: 1.069 | L27: 1.023 | M27: =1/K27 -> 0.9354537 | N27: Afro | O27: Black | P27: Clean shaven | Q27: Long and narrow | R27: Regular | S27: Brown | T27: Brown | U27: Very lean, toned | V27: Classic trunks | W27: Emerald | X27: White | Y27: Bare chest | Z27: No | AA27: Black | AB27: High boots · Gold | AC27: Gum
A28: Pro | B28: 12 | C28: Felix Dlamini | D28: Riptide | E28: Manila | F28: Swarmer | G28: Walks you down and never stops throwing. Lives on the inside with hooks. | H28: Left hook | I28: 0.436 | J28: =MAX(1,MIN(10,ROUND(I28*8+IF(A28="Amateur",0.5,1),0))) -> 4 | K28: 1.061 | L28: 1.017 | M28: =1/K28 -> 0.94250707 | N28: Bald | P28: Clean shaven | Q28: Brawler | R28: Regular | S28: Brown | T28: Dark brown | U28: Heavy, built | V28: Classic trunks | W28: Navy | X28: Silver | Y28: Bare chest | Z28: No | AA28: Silver | AB28: Classic boots · Blue | AC28: Gum
A29: Pro | B29: 13 | C29: Thiago Sandoval | D29: Yardstick | E29: Tbilisi | F29: Out-boxer | G29: Stays long behind a stiff jab and keeps moving. Hard to reach, rarely trades. | H29: Stiff cross | I29: 0.407 | J29: =MAX(1,MIN(10,ROUND(I29*8+IF(A29="Amateur",0.5,1),0))) -> 4 | K29: 1.054 | L29: 1.011 | M29: =1/K29 -> 0.9487666 | N29: Buzzed | O29: Blond | P29: Clean shaven | Q29: Original | R29: Regular | S29: Olive | T29: Grey | U29: Lean, built | V29: Long trunks | W29: Red | X29: Green | Y29: Bare chest | Z29: No | AA29: White | AB29: Classic boots · Black | AC29: White
A30: Pro | B30: 14 | C30: Leon Coyle | D30: Buzzsaw | E30: Accra | F30: Swarmer | G30: Walks you down and never stops throwing. Lives on the inside with hooks. | H30: Uppercut | I30: 0.379 | J30: =MAX(1,MIN(10,ROUND(I30*8+IF(A30="Amateur",0.5,1),0))) -> 4 | K30: 1.047 | L30: 1.006 | M30: =1/K30 -> 0.95510984 | N30: Faux hawk | O30: Blond | P30: Clean shaven | Q30: Brawler | R30: Regular | S30: Dark brown | T30: Brown | U30: Heavy, bodybuilder | V30: Long trunks | W30: Black | X30: Green | Y30: Bare chest | Z30: No | AA30: Green | AB30: Low boots · Black | AC30: White
A31: Pro | B31: 15 | C31: Malik Sandoval | D31: The Plumber | E31: Recife | F31: Body snatcher | G31: Digs to the ribs and the liver round after round until your legs go. | H31: Body jab | I31: 0.35 | J31: =MAX(1,MIN(10,ROUND(I31*8+IF(A31="Amateur",0.5,1),0))) -> 4 | K31: 1.04 | L31: 1 | M31: =1/K31 -> 0.96153846 | N31: Pompadour | O31: Brown | P31: Clean shaven | Q31: Round and soft | R31: Regular | S31: Dark brown | T31: Hazel | U31: Middleweight, built | V31: Long trunks | W31: Emerald | X31: Navy | Y31: Bare chest | Z31: No | AA31: Navy | AB31: Classic boots · Silver | AC31: Black
A32: Ultimate | B32: 1 | C32: Kenji Haddad | D32: Hailstorm | E32: Gothenburg | F32: Volume puncher | G32: Fast, light punches in long bunches. Wins rounds on work rate. | H32: Left hook | I32: 1 | J32: =MAX(1,MIN(10,ROUND(I32*8+IF(A32="Amateur",0.5,1),0))) -> 9 | K32: 1.34 | L32: 1.062 | M32: =1/K32 -> 0.74626866 | N32: Faux hawk | O32: Blond | P32: Beard | Q32: Brawler | R32: Regular | S32: Light | T32: Grey | U32: Lean, built | V32: Classic trunks | W32: Red | X32: Teal | Y32: Bare chest | Z32: No | AA32: Red | AB32: Low boots · Red | AC32: White
A33: Ultimate | B33: 2 | C33: Dmitri Yilmaz | D33: Woodpecker | E33: Gothenburg | F33: Volume puncher | G33: Fast, light punches in long bunches. Wins rounds on work rate. | H33: Body jab | I33: 0.987 | J33: =MAX(1,MIN(10,ROUND(I33*8+IF(A33="Amateur",0.5,1),0))) -> 9 | K33: 1.333 | L33: 1.058 | M33: =1/K33 -> 0.75018755 | N33: Buzzed | O33: Red dye | P33: Beard | Q33: Brawler | R33: Regular | S33: Tan | T33: Blue | U33: Middleweight, built | V33: Classic trunks | W33: Teal | X33: Silver | Y33: Bare chest | Z33: No | AA33: Black | AB33: Classic boots · Red | AC33: Gum
A34: Ultimate | B34: 3 | C34: Ulises Zamora | D34: Boulder | E34: Izmir | F34: Slugger | G34: Slow feet, heavy hands. Waits for one big hook or uppercut to end it. | H34: Long right hook | I34: 0.975 | J34: =MAX(1,MIN(10,ROUND(I34*8+IF(A34="Amateur",0.5,1),0))) -> 9 | K34: 1.327 | L34: 1.313 | M34: =1/K34 -> 0.7535795 | N34: Simple parted | O34: Dark brown | P34: Clean shaven | Q34: Brawler | R34: Regular | S34: Fair | T34: Grey | U34: Heavyweight, toned | V34: Classic trunks | W34: Black | X34: Blue | Y34: Bare chest | Z34: No | AA34: Black | AB34: Classic boots · Blue | AC34: White
A35: Ultimate | B35: 4 | C35: Farid Dlamini | D35: Encore | E35: Bristol | F35: Showman | G35: Flashy and loud. Throws in flurries, taunts when ahead, can be caught showing off. | H35: Left hook | I35: 0.962 | J35: =MAX(1,MIN(10,ROUND(I35*8+IF(A35="Amateur",0.5,1),0))) -> 9 | K35: 1.32 | L35: 1.168 | M35: =1/K35 -> 0.75757576 | N35: Afro | O35: Red dye | P35: Clean shaven | Q35: Brawler | R35: Regular | S35: Dark brown | T35: Green | U35: Middleweight, bodybuilder | V35: Long trunks | W35: Crimson | X35: Purple | Y35: Bare chest | Z35: No | AA35: Crimson | AB35: Classic boots · Silver | AC35: Black
A36: Ultimate | B36: 5 | C36: Aleksander Walsh | D36: Bunker | E36: Bristol | F36: Shell guard | G36: Hides behind a high guard, takes your best shots on the arms, then breaks yours. | H36: Uppercut | I36: 0.949 | J36: =MAX(1,MIN(10,ROUND(I36*8+IF(A36="Amateur",0.5,1),0))) -> 9 | K36: 1.418 | L36: 1.164 | M36: =1/K36 -> 0.70521862 | N36: Faux hawk | O36: Auburn | P36: Clean shaven | Q36: Brawler | R36: Regular | S36: Dark brown | T36: Dark brown | U36: Middleweight, bodybuilder | V36: Classic trunks | W36: White | X36: Maroon | Y36: Bare chest | Z36: No | AA36: Black | AB36: High boots · Silver | AC36: Gum
A37: Ultimate | B37: 6 | C37: Arjun Adeyemi | D37: Iron Gate | E37: Tijuana | F37: Shell guard | G37: Hides behind a high guard, takes your best shots on the arms, then breaks yours. | H37: Uppercut | I37: 0.937 | J37: =MAX(1,MIN(10,ROUND(I37*8+IF(A37="Amateur",0.5,1),0))) -> 8 | K37: 1.411 | L37: 1.16 | M37: =1/K37 -> 0.70871722 | N37: High-top fade | O37: Ginger | P37: Beard | Q37: Brawler | R37: Thin | S37: Tan | T37: Grey | U37: Heavy, bodybuilder | V37: Long trunks | W37: Crimson | X37: Silver | Y37: Bare chest | Z37: No | AA37: Crimson | AB37: High boots · Blue | AC37: Gum
A38: Ultimate | B38: 7 | C38: Lucas Dossou | D38: Matador | E38: Naples | F38: Slick defender | G38: Slips, ducks and rolls everything, then pecks at you from odd angles. | H38: Double jab | I38: 0.924 | J38: =MAX(1,MIN(10,ROUND(I38*8+IF(A38="Amateur",0.5,1),0))) -> 8 | K38: 1.3 | L38: 1.156 | M38: =1/K38 -> 0.76923077 | N38: Twists | O38: Grey | P38: Clean shaven | Q38: Brawler | R38: Regular | S38: Brown | T38: Grey | U38: Lean, toned | V38: Long trunks | W38: Red | X38: Black | Y38: Bare chest | Z38: No | AA38: Black | AB38: High boots · Red | AC38: White
A39: Ultimate | B39: 8 | C39: Tomas Dossou | D39: The Fencer | E39: Izmir | F39: Out-boxer | G39: Stays long behind a stiff jab and keeps moving. Hard to reach, rarely trades. | H39: Double jab | I39: 0.911 | J39: =MAX(1,MIN(10,ROUND(I39*8+IF(A39="Amateur",0.5,1),0))) -> 8 | K39: 1.293 | L39: 1.152 | M39: =1/K39 -> 0.7733952 | N39: Bald | P39: Clean shaven | Q39: Brawler | R39: Thin | S39: Brown | T39: Grey | U39: Lean, toned | V39: Long trunks | W39: Pink | X39: Orange | Y39: Bare chest | Z39: No | AA39: Pink | AB39: Classic boots · White | AC39: Gum
A40: Ultimate | B40: 9 | C40: Viktor Sandoval | D40: The Professor | E40: Rotterdam | F40: Out-boxer | G40: Stays long behind a stiff jab and keeps moving. Hard to reach, rarely trades. | H40: Body jab | I40: 0.899 | J40: =MAX(1,MIN(10,ROUND(I40*8+IF(A40="Amateur",0.5,1),0))) -> 8 | K40: 1.287 | L40: 1.148 | M40: =1/K40 -> 0.77700078 | N40: Crew cut | O40: Auburn | P40: Clean shaven | Q40: Long and narrow | R40: Regular | S40: Olive | T40: Green | U40: Lean, toned | V40: Classic trunks | W40: Gold | X40: Teal | Y40: Bare chest | Z40: No | AA40: Teal | AB40: High boots · Black | AC40: Gum
A41: Ultimate | B41: 10 | C41: Nnamdi Osei | D41: Wildfire | E41: Osaka | F41: Swarmer | G41: Walks you down and never stops throwing. Lives on the inside with hooks. | H41: Body hook | I41: 0.886 | J41: =MAX(1,MIN(10,ROUND(I41*8+IF(A41="Amateur",0.5,1),0))) -> 8 | K41: 1.28 | L41: 1.144 | M41: =1/K41 -> 0.78125 | N41: Bald | P41: Clean shaven | Q41: Wide nose | R41: Regular | S41: Olive | T41: Brown | U41: Middleweight, built | V41: Classic trunks | W41: Maroon | X41: Green | Y41: Bare chest | Z41: No | AA41: White | AB41: High boots · Gold | AC41: Gum
A42: Ultimate | B42: 11 | C42: Jonah Moretti | D42: Return Fire | E42: Glasgow | F42: Counter-puncher | G42: Lets you lead, slips or blocks, then fires back before you reset. | H42: Stiff cross | I42: 0.873 | J42: =MAX(1,MIN(10,ROUND(I42*8+IF(A42="Amateur",0.5,1),0))) -> 8 | K42: 1.273 | L42: 1.14 | M42: =1/K42 -> 0.78554595 | N42: Mohawk | O42: Grey | P42: Clean shaven | Q42: Original | R42: Thin | S42: Dark brown | T42: Dark brown | U42: Middleweight, built | V42: Long trunks | W42: Emerald | X42: Teal | Y42: Bare chest | Z42: No | AA42: Black | AB42: Classic boots · Red | AC42: Black
A43: Ultimate | B43: 12 | C43: Amadou Fontaine | D43: Body Bag | E43: Nairobi | F43: Body snatcher | G43: Digs to the ribs and the liver round after round until your legs go. | H43: Liver shot | I43: 0.861 | J43: =MAX(1,MIN(10,ROUND(I43*8+IF(A43="Amateur",0.5,1),0))) -> 8 | K43: 1.267 | L43: 1.136 | M43: =1/K43 -> 0.78926598 | N43: Crew cut | O43: Brown | P43: Clean shaven | Q43: Brawler | R43: Regular | S43: Fair | T43: Hazel | U43: Middleweight, built | V43: Long trunks | W43: Emerald | X43: Maroon | Y43: Bare chest | Z43: No | AA43: Emerald | AB43: High boots · Gold | AC43: Black
A44: Ultimate | B44: 13 | C44: Rafael Iwu | D44: Razzle | E44: Rotterdam | F44: Showman | G44: Flashy and loud. Throws in flurries, taunts when ahead, can be caught showing off. | H44: Left hook | I44: 0.848 | J44: =MAX(1,MIN(10,ROUND(I44*8+IF(A44="Amateur",0.5,1),0))) -> 8 | K44: 1.26 | L44: 1.132 | M44: =1/K44 -> 0.79365079 | N44: Buzzed | O44: Blond | P44: Beard | Q44: Brawler | R44: Regular | S44: Light | T44: Dark brown | U44: Middleweight, bodybuilder | V44: Classic trunks | W44: Pink | X44: Emerald | Y44: Bare chest | Z44: No | AA44: Emerald | AB44: Low boots · Red | AC44: White
...

Sheet Styles
A1: Style | B1: How he fights | C1: Likes to fight at | D1: Favourite game plan | E1: Throws most | F1: Changes to his skill | G1: Fighters
A2: Out-boxer | B2: Stays long behind a stiff jab and keeps moving. Hard to reach, rarely trades. | C2: Long range | D2: Boxing at range | E2: straight x1.9 | F2: work rate -10%, defence +15%, dodging +10%, combinations -15% | G2: =COUNTIF(Roster!F:F,A2) -> 8
A3: Swarmer | B3: Walks you down and never stops throwing. Lives on the inside with hooks. | C3: In close | D3: Pressure | E3: hook x1.6, upper x1.2, body x1.2 | F3: work rate +35%, combinations +30%, pause between moves -20%, defence -15% | G3: =COUNTIF(Roster!F:F,A3) -> 8
A4: Slugger | B4: Slow feet, heavy hands. Waits for one big hook or uppercut to end it. | C4: Medium-close | D4: Adapts to you | E4: hook x1.8, upper x1.7, power x1.6 | F4: work rate -20%, combinations -40%, pause between moves +25%, defence -20%, dodging -40%, power x1.12 | G4: =COUNTIF(Roster!F:F,A4) -> 8
A5: Counter-puncher | B5: Lets you lead, slips or blocks, then fires back before you reset. | C5: Medium-long | D5: Countering | E5: straight x1.3, hook x1.2 | F5: work rate -35%, punishing misses +40%, reaction time -15%, dodging +25%, reading punches +5% | G5: =COUNTIF(Roster!F:F,A5) -> 8
A6: Body snatcher | B6: Digs to the ribs and the liver round after round until your legs go. | C6: Medium-close | D6: Body work | E6: body x2.5, power x1.3 | F6: work rate +5%, combinations +10% | G6: =COUNTIF(Roster!F:F,A6) -> 7
A7: Slick defender | B7: Slips, ducks and rolls everything, then pecks at you from odd angles. | C7: Medium-long | D7: Adapts to you | E7: straight x1.2, hook x1.1, upper x1.1 | F7: dodging +60%, defence +25%, work rate -15%, reaction time -15% | G7: =COUNTIF(Roster!F:F,A7) -> 7
A8: Volume puncher | B8: Fast, light punches in long bunches. Wins rounds on work rate. | C8: Middle distance | D8: Adapts to you | E8: straight x1.5, hook x1.1, body x1.1 | F8: work rate +45%, combinations +40%, pause between moves -30%, power x0.9 | G8: =COUNTIF(Roster!F:F,A8) -> 5
A9: Shell guard | B9: Hides behind a high guard, takes your best shots on the arms, then breaks yours. | C9: Middle distance | D9: Adapts to you | E9: power x2.2, hook x1.2 | F9: defence +45%, dodging -55%, work rate -15%, punishing misses +20%, toughness x1.08 | G9: =COUNTIF(Roster!F:F,A9) -> 5
A10: Showman | B10: Flashy and loud. Throws in flurries, taunts when ahead, can be caught showing off. | C10: Middle distance | D10: Adapts to you | E10: upper x1.5, hook x1.3 | F10: work rate +15%, combinations +25%, taunting +400%, defence -10%, reading punches -5% | G10: =COUNTIF(Roster!F:F,A10) -> 5

Sheet Tournaments
A1: Tournament | B1: Short name | C1: Fighters | D1: Rounds | E1: Opponents | F1: Weakest skill | G1: Strongest skill | H1: Toughness from | I1: Toughness to | J1: Toughness growth per round
A2: Amateur Boxing Championship | B2: Amateur | C2: 16 | D2: =LOG(C2,2) -> 4 | E2: =COUNTIF(Roster!A:A,B2) -> 15 | F2: =_xlfn.MINIFS(Roster!I:I,Roster!A:A,B2) -> 0 | G2: =_xlfn.MAXIFS(Roster!I:I,Roster!A:A,B2) -> 0.45 | H2: =_xlfn.MINIFS(Roster!K:K,Roster!A:A,B2) -> 1 | I2: =_xlfn.MAXIFS(Roster!K:K,Roster!A:A,B2) -> 1.08 | J2: 0
A3: Pro Boxing Championship | B3: Pro | C3: 16 | D3: =LOG(C3,2) -> 4 | E3: =COUNTIF(Roster!A:A,B3) -> 15 | F3: =_xlfn.MINIFS(Roster!I:I,Roster!A:A,B3) -> 0.35 | G3: =_xlfn.MAXIFS(Roster!I:I,Roster!A:A,B3) -> 0.75 | H3: =_xlfn.MINIFS(Roster!K:K,Roster!A:A,B3) -> 1.04 | I3: =_xlfn.MAXIFS(Roster!K:K,Roster!A:A,B3) -> 1.216 | J3: 0
A4: Ultimate Boxing Championship | B4: Ultimate | C4: 32 | D4: =LOG(C4,2) -> 5 | E4: =COUNTIF(Roster!A:A,B4) -> 31 | F4: =_xlfn.MINIFS(Roster!I:I,Roster!A:A,B4) -> 0.62 | G4: =_xlfn.MAXIFS(Roster!I:I,Roster!A:A,B4) -> 1 | H4: =_xlfn.MINIFS(Roster!K:K,Roster!A:A,B4) -> 1.14 | I4: =_xlfn.MAXIFS(Roster!K:K,Roster!A:A,B4) -> 1.418 | J4: 0.07
A6: You make up the last place in every draw: Fighters = Opponents + 1. Blue numbers are inputs; the rest are formulas.
